[2024-07-12T09:19:03.244+0000] {taskinstance.py:1957} INFO - Dependencies all met for dep_context=non-requeueable deps ti=<TaskInstance: store_data_from_kaggle.check_load manual__2024-07-12T09:18:40.219118+00:00 [queued]>
[2024-07-12T09:19:03.254+0000] {taskinstance.py:1957} INFO - Dependencies all met for dep_context=requeueable deps ti=<TaskInstance: store_data_from_kaggle.check_load manual__2024-07-12T09:18:40.219118+00:00 [queued]>
[2024-07-12T09:19:03.255+0000] {taskinstance.py:2171} INFO - Starting attempt 1 of 1
[2024-07-12T09:19:03.276+0000] {taskinstance.py:2192} INFO - Executing <Task(_PythonExternalDecoratedOperator): check_load> on 2024-07-12 09:18:40.219118+00:00
[2024-07-12T09:19:03.285+0000] {standard_task_runner.py:60} INFO - Started process 465 to run task
[2024-07-12T09:19:03.292+0000] {standard_task_runner.py:87} INFO - Running: ['***', 'tasks', 'run', 'store_data_from_kaggle', 'check_load', 'manual__2024-07-12T09:18:40.219118+00:00', '--job-id', '36', '--raw', '--subdir', 'DAGS_FOLDER/pipeline.py', '--cfg-path', '/tmp/tmpp5ofl2f4']
[2024-07-12T09:19:03.295+0000] {standard_task_runner.py:88} INFO - Job 36: Subtask check_load
[2024-07-12T09:19:03.387+0000] {task_command.py:423} INFO - Running <TaskInstance: store_data_from_kaggle.check_load manual__2024-07-12T09:18:40.219118+00:00 [running]> on host ed07ad5522de
[2024-07-12T09:19:03.510+0000] {taskinstance.py:2481} INFO - Exporting env vars: AIRFLOW_CTX_DAG_OWNER='***' AIRFLOW_CTX_DAG_ID='store_data_from_kaggle' AIRFLOW_CTX_TASK_ID='check_load' AIRFLOW_CTX_EXECUTION_DATE='2024-07-12T09:18:40.219118+00:00' AIRFLOW_CTX_TRY_NUMBER='1' AIRFLOW_CTX_DAG_RUN_ID='manual__2024-07-12T09:18:40.219118+00:00'
[2024-07-12T09:19:03.563+0000] {python.py:903} WARNING - When checking for Airflow installed in virtual environment got Command '['/opt/airflow/soda_venv/bin/python', '-c', 'from airflow import __version__; print(__version__)']' returned non-zero exit status 1.
[2024-07-12T09:19:03.565+0000] {python.py:904} WARNING - This means that Airflow is not properly installed by  /opt/***/soda_venv/bin/python. Airflow context keys will not be available. Please Install Airflow 2.8.0 in your environment to access them.
[2024-07-12T09:19:03.928+0000] {process_utils.py:182} INFO - Executing cmd: /opt/***/soda_venv/bin/python /tmp/venv-calllpqifzim/script.py /tmp/venv-calllpqifzim/script.in /tmp/venv-calllpqifzim/script.out /tmp/venv-calllpqifzim/string_args.txt /tmp/venv-calllpqifzim/termination.log
[2024-07-12T09:19:03.941+0000] {process_utils.py:186} INFO - Output:
[2024-07-12T09:19:04.553+0000] {process_utils.py:190} INFO - [09:19:04] Invalid configuration header: expected "data_source {data source name}".
[2024-07-12T09:19:04.554+0000] {process_utils.py:190} INFO -   +-> line=None,col=None in /opt/***/include/soda/configuration.yml
[2024-07-12T09:19:04.658+0000] {process_utils.py:190} INFO - [09:19:04] Invalid section header "tables"
[2024-07-12T09:19:04.664+0000] {process_utils.py:190} INFO -   +-> line=1,col=1 in /opt/***/include/soda/checks/sources/checks.yml
[2024-07-12T09:19:04.965+0000] {process_utils.py:190} INFO - [09:19:04] No valid checks found, 0 checks evaluated.
[2024-07-12T09:19:04.966+0000] {process_utils.py:190} INFO - [09:19:04] Invalid configuration header: expected "data_source {data source name}".
[2024-07-12T09:19:04.966+0000] {process_utils.py:190} INFO -   +-> line=None,col=None in /opt/***/include/soda/configuration.yml
[2024-07-12T09:19:04.967+0000] {process_utils.py:190} INFO - [09:19:04] Invalid section header "tables"
[2024-07-12T09:19:04.968+0000] {process_utils.py:190} INFO -   +-> line=1,col=1 in /opt/***/include/soda/checks/sources/checks.yml
[2024-07-12T09:19:05.110+0000] {process_utils.py:190} INFO - [09:19:05] Error while executing Soda Cloud command response code: 400
[2024-07-12T09:19:05.111+0000] {process_utils.py:190} INFO - Running Soda Scan ...
[2024-07-12T09:19:05.112+0000] {process_utils.py:190} INFO - INFO   | Soda Core 3.0.45
[2024-07-12T09:19:05.112+0000] {process_utils.py:190} INFO - DEBUG  | Reading configuration file "/opt/***/include/soda/configuration.yml"
[2024-07-12T09:19:05.113+0000] {process_utils.py:190} INFO - ERROR  | Invalid configuration header: expected "data_source {data source name}". | line=None,col=None in /opt/***/include/soda/configuration.yml
[2024-07-12T09:19:05.114+0000] {process_utils.py:190} INFO - DEBUG  | Reading SodaCL file "/opt/***/include/soda/checks/sources/checks.yml"
[2024-07-12T09:19:05.114+0000] {process_utils.py:190} INFO - ERROR  | Invalid section header "tables" | line=1,col=1 in /opt/***/include/soda/checks/sources/checks.yml
[2024-07-12T09:19:05.115+0000] {process_utils.py:190} INFO - DEBUG  | Scan execution starts
[2024-07-12T09:19:05.115+0000] {process_utils.py:190} INFO - INFO   | Scan summary:
[2024-07-12T09:19:05.116+0000] {process_utils.py:190} INFO - WARNING| No valid checks found, 0 checks evaluated.
[2024-07-12T09:19:05.116+0000] {process_utils.py:190} INFO - INFO   | 2 errors.
[2024-07-12T09:19:05.117+0000] {process_utils.py:190} INFO - INFO   | Oops! 2 errors. 0 failures. 0 warnings. 0 pass.
[2024-07-12T09:19:05.118+0000] {process_utils.py:190} INFO - INFO   | Sending results to Soda Cloud
[2024-07-12T09:19:05.119+0000] {process_utils.py:190} INFO - ERROR  | Error while executing Soda Cloud command response code: 400
[2024-07-12T09:19:05.120+0000] {process_utils.py:190} INFO - DEBUG  | {
[2024-07-12T09:19:05.121+0000] {process_utils.py:190} INFO -   "type": "_ROOT",
[2024-07-12T09:19:05.121+0000] {process_utils.py:190} INFO -   "code": "invalid_request",
[2024-07-12T09:19:05.123+0000] {process_utils.py:190} INFO -   "message": "Failed validation of SodaCoreInsertScanResultsCommand on the following properties: \n logs[2].errorLocation.line: must not be empty\nlogs[2].errorLocation.col: must not be empty"
[2024-07-12T09:19:05.123+0000] {process_utils.py:190} INFO - }
[2024-07-12T09:19:05.124+0000] {process_utils.py:190} INFO - INFO   | Soda Cloud Trace: 8286545803421496024
[2024-07-12T09:19:05.125+0000] {process_utils.py:190} INFO - Traceback (most recent call last):
[2024-07-12T09:19:05.125+0000] {process_utils.py:190} INFO -   File "/tmp/venv-calllpqifzim/script.py", line 39, in <module>
[2024-07-12T09:19:05.126+0000] {process_utils.py:190} INFO -     res = check_load(*arg_dict["args"], **arg_dict["kwargs"])
[2024-07-12T09:19:05.137+0000] {process_utils.py:190} INFO -   File "/tmp/venv-calllpqifzim/script.py", line 36, in check_load
[2024-07-12T09:19:05.145+0000] {process_utils.py:190} INFO -     a = run_soda_scan(project_root = PROJECT_ROOT, scan_name ="checks_ingest", checks_subpath = "sources/checks.yml")
[2024-07-12T09:19:05.145+0000] {process_utils.py:190} INFO -   File "/opt/***/include/soda/check_function.py", line 46, in run_soda_scan
[2024-07-12T09:19:05.146+0000] {process_utils.py:190} INFO -     raise ValueError('Soda Scan failed')
[2024-07-12T09:19:05.146+0000] {process_utils.py:190} INFO - ValueError: Soda Scan failed
[2024-07-12T09:19:05.197+0000] {taskinstance.py:2699} ERROR - Task failed with exception
Traceback (most recent call last):
  File "/home/airflow/.local/lib/python3.8/site-packages/airflow/models/taskinstance.py", line 433, in _execute_task
    result = execute_callable(context=context, **execute_callable_kwargs)
  File "/home/airflow/.local/lib/python3.8/site-packages/airflow/decorators/base.py", line 242, in execute
    return_value = super().execute(context)
  File "/home/airflow/.local/lib/python3.8/site-packages/airflow/operators/python.py", line 400, in execute
    return super().execute(context=serializable_context)
  File "/home/airflow/.local/lib/python3.8/site-packages/airflow/operators/python.py", line 199, in execute
    return_value = self.execute_callable()
  File "/home/airflow/.local/lib/python3.8/site-packages/airflow/operators/python.py", line 851, in execute_callable
    return self._execute_python_callable_in_subprocess(python_path)
  File "/home/airflow/.local/lib/python3.8/site-packages/airflow/operators/python.py", line 471, in _execute_python_callable_in_subprocess
    raise AirflowException(error_msg) from None
airflow.exceptions.AirflowException: Process returned non-zero exit status 1.
Soda Scan failed
[2024-07-12T09:19:05.202+0000] {taskinstance.py:1138} INFO - Marking task as FAILED. dag_id=store_data_from_kaggle, task_id=check_load, execution_date=20240712T091840, start_date=20240712T091903, end_date=20240712T091905
[2024-07-12T09:19:05.224+0000] {standard_task_runner.py:107} ERROR - Failed to execute job 36 for task check_load (Process returned non-zero exit status 1.
Soda Scan failed; 465)
[2024-07-12T09:19:05.243+0000] {local_task_job_runner.py:234} INFO - Task exited with return code 1
[2024-07-12T09:19:05.277+0000] {taskinstance.py:3281} INFO - 0 downstream tasks scheduled from follow-on schedule check
