[2024-07-12T06:31:43.455+0000] {taskinstance.py:1957} INFO - Dependencies all met for dep_context=non-requeueable deps ti=<TaskInstance: store_data_from_kaggle.check_report manual__2024-07-12T06:30:42.593332+00:00 [queued]>
[2024-07-12T06:31:43.469+0000] {taskinstance.py:1957} INFO - Dependencies all met for dep_context=requeueable deps ti=<TaskInstance: store_data_from_kaggle.check_report manual__2024-07-12T06:30:42.593332+00:00 [queued]>
[2024-07-12T06:31:43.470+0000] {taskinstance.py:2171} INFO - Starting attempt 1 of 1
[2024-07-12T06:31:43.501+0000] {taskinstance.py:2192} INFO - Executing <Task(_PythonExternalDecoratedOperator): check_report> on 2024-07-12 06:30:42.593332+00:00
[2024-07-12T06:31:43.511+0000] {standard_task_runner.py:60} INFO - Started process 941 to run task
[2024-07-12T06:31:43.523+0000] {standard_task_runner.py:87} INFO - Running: ['***', 'tasks', 'run', 'store_data_from_kaggle', 'check_report', 'manual__2024-07-12T06:30:42.593332+00:00', '--job-id', '20', '--raw', '--subdir', 'DAGS_FOLDER/pipeline.py', '--cfg-path', '/tmp/tmp4geo167z']
[2024-07-12T06:31:43.527+0000] {standard_task_runner.py:88} INFO - Job 20: Subtask check_report
[2024-07-12T06:31:43.591+0000] {task_command.py:423} INFO - Running <TaskInstance: store_data_from_kaggle.check_report manual__2024-07-12T06:30:42.593332+00:00 [running]> on host 97943abcf112
[2024-07-12T06:31:43.666+0000] {taskinstance.py:2481} INFO - Exporting env vars: AIRFLOW_CTX_DAG_OWNER='***' AIRFLOW_CTX_DAG_ID='store_data_from_kaggle' AIRFLOW_CTX_TASK_ID='check_report' AIRFLOW_CTX_EXECUTION_DATE='2024-07-12T06:30:42.593332+00:00' AIRFLOW_CTX_TRY_NUMBER='1' AIRFLOW_CTX_DAG_RUN_ID='manual__2024-07-12T06:30:42.593332+00:00'
[2024-07-12T06:31:43.706+0000] {python.py:903} WARNING - When checking for Airflow installed in virtual environment got Command '['/opt/airflow/soda_venv/bin/python', '-c', 'from airflow import __version__; print(__version__)']' returned non-zero exit status 1.
[2024-07-12T06:31:43.707+0000] {python.py:904} WARNING - This means that Airflow is not properly installed by  /opt/***/soda_venv/bin/python. Airflow context keys will not be available. Please Install Airflow 2.8.0 in your environment to access them.
[2024-07-12T06:31:44.093+0000] {process_utils.py:182} INFO - Executing cmd: /opt/***/soda_venv/bin/python /tmp/venv-call55rap_0b/script.py /tmp/venv-call55rap_0b/script.in /tmp/venv-call55rap_0b/script.out /tmp/venv-call55rap_0b/string_args.txt /tmp/venv-call55rap_0b/termination.log
[2024-07-12T06:31:44.108+0000] {process_utils.py:186} INFO - Output:
[2024-07-12T06:31:45.302+0000] {process_utils.py:190} INFO - [06:31:45] Invalid configuration header: expected "data_source {data source name}".
[2024-07-12T06:31:45.315+0000] {process_utils.py:190} INFO -   +-> line=None,col=None in /opt/***/include/soda/configuration.yml
[2024-07-12T06:31:46.086+0000] {process_utils.py:190} INFO - [06:31:46] Data source 'online_retail' not present in the configuration. Configured data sources:
[2024-07-12T06:31:46.087+0000] {process_utils.py:190} INFO - [06:31:46] No valid checks found, 0 checks evaluated.
[2024-07-12T06:31:46.088+0000] {process_utils.py:190} INFO - [06:31:46] Invalid configuration header: expected "data_source {data source name}".
[2024-07-12T06:31:46.088+0000] {process_utils.py:190} INFO -   +-> line=None,col=None in /opt/***/include/soda/configuration.yml
[2024-07-12T06:31:46.089+0000] {process_utils.py:190} INFO - [06:31:46] Data source 'online_retail' not present in the configuration. Configured data sources:
[2024-07-12T06:31:47.126+0000] {process_utils.py:190} INFO - [06:31:47] Error while executing Soda Cloud command response code: 400
[2024-07-12T06:31:47.126+0000] {process_utils.py:190} INFO - Running Soda Scan ...
[2024-07-12T06:31:47.135+0000] {process_utils.py:190} INFO - INFO   | Soda Core 3.0.45
[2024-07-12T06:31:47.135+0000] {process_utils.py:190} INFO - DEBUG  | Reading configuration file "/opt/***/include/soda/configuration.yml"
[2024-07-12T06:31:47.135+0000] {process_utils.py:190} INFO - ERROR  | Invalid configuration header: expected "data_source {data source name}". | line=None,col=None in /opt/***/include/soda/configuration.yml
[2024-07-12T06:31:47.136+0000] {process_utils.py:190} INFO - DEBUG  | Reading SodaCL file "/opt/***/include/soda/checks/report/report_customer_invoices.yml"
[2024-07-12T06:31:47.136+0000] {process_utils.py:190} INFO - DEBUG  | Reading SodaCL file "/opt/***/include/soda/checks/report/report_year_invoices.yml"
[2024-07-12T06:31:47.136+0000] {process_utils.py:190} INFO - DEBUG  | Reading SodaCL file "/opt/***/include/soda/checks/report/report_product_invoices.yml"
[2024-07-12T06:31:47.143+0000] {process_utils.py:190} INFO - DEBUG  | Scan execution starts
[2024-07-12T06:31:47.151+0000] {process_utils.py:190} INFO - ERROR  | Data source 'online_retail' not present in the configuration. Configured data sources:
[2024-07-12T06:31:47.151+0000] {process_utils.py:190} INFO - INFO   | Scan summary:
[2024-07-12T06:31:47.151+0000] {process_utils.py:190} INFO - WARNING| No valid checks found, 0 checks evaluated.
[2024-07-12T06:31:47.151+0000] {process_utils.py:190} INFO - INFO   | 2 errors.
[2024-07-12T06:31:47.152+0000] {process_utils.py:190} INFO - INFO   | Oops! 2 errors. 0 failures. 0 warnings. 0 pass.
[2024-07-12T06:31:47.152+0000] {process_utils.py:190} INFO - INFO   | Sending results to Soda Cloud
[2024-07-12T06:31:47.152+0000] {process_utils.py:190} INFO - ERROR  | Error while executing Soda Cloud command response code: 400
[2024-07-12T06:31:47.152+0000] {process_utils.py:190} INFO - DEBUG  | {
[2024-07-12T06:31:47.152+0000] {process_utils.py:190} INFO -   "type": "_ROOT",
[2024-07-12T06:31:47.153+0000] {process_utils.py:190} INFO -   "code": "invalid_request",
[2024-07-12T06:31:47.153+0000] {process_utils.py:190} INFO -   "message": "Failed validation of SodaCoreInsertScanResultsCommand on the following properties: \n logs[2].errorLocation.col: must not be empty\nlogs[2].errorLocation.line: must not be empty"
[2024-07-12T06:31:47.155+0000] {process_utils.py:190} INFO - }
[2024-07-12T06:31:47.155+0000] {process_utils.py:190} INFO - INFO   | Soda Cloud Trace: 2430171215091079453
[2024-07-12T06:31:47.167+0000] {process_utils.py:190} INFO - Traceback (most recent call last):
[2024-07-12T06:31:47.167+0000] {process_utils.py:190} INFO -   File "/tmp/venv-call55rap_0b/script.py", line 36, in <module>
[2024-07-12T06:31:47.171+0000] {process_utils.py:190} INFO -     res = check_report(*arg_dict["args"], **arg_dict["kwargs"])
[2024-07-12T06:31:47.179+0000] {process_utils.py:190} INFO -   File "/tmp/venv-call55rap_0b/script.py", line 33, in check_report
[2024-07-12T06:31:47.179+0000] {process_utils.py:190} INFO -     a = run_soda_scan(project_root = PROJECT_ROOT, scan_name ="checks_report", checks_subpath = "report")
[2024-07-12T06:31:47.179+0000] {process_utils.py:190} INFO -   File "/opt/***/include/soda/check_function.py", line 46, in run_soda_scan
[2024-07-12T06:31:47.180+0000] {process_utils.py:190} INFO -     raise ValueError('Soda Scan failed')
[2024-07-12T06:31:47.180+0000] {process_utils.py:190} INFO - ValueError: Soda Scan failed
[2024-07-12T06:31:47.536+0000] {taskinstance.py:2699} ERROR - Task failed with exception
Traceback (most recent call last):
  File "/home/airflow/.local/lib/python3.8/site-packages/airflow/models/taskinstance.py", line 433, in _execute_task
    result = execute_callable(context=context, **execute_callable_kwargs)
  File "/home/airflow/.local/lib/python3.8/site-packages/airflow/decorators/base.py", line 242, in execute
    return_value = super().execute(context)
  File "/home/airflow/.local/lib/python3.8/site-packages/airflow/operators/python.py", line 400, in execute
    return super().execute(context=serializable_context)
  File "/home/airflow/.local/lib/python3.8/site-packages/airflow/operators/python.py", line 199, in execute
    return_value = self.execute_callable()
  File "/home/airflow/.local/lib/python3.8/site-packages/airflow/operators/python.py", line 851, in execute_callable
    return self._execute_python_callable_in_subprocess(python_path)
  File "/home/airflow/.local/lib/python3.8/site-packages/airflow/operators/python.py", line 471, in _execute_python_callable_in_subprocess
    raise AirflowException(error_msg) from None
airflow.exceptions.AirflowException: Process returned non-zero exit status 1.
Soda Scan failed
[2024-07-12T06:31:47.572+0000] {taskinstance.py:1138} INFO - Marking task as FAILED. dag_id=store_data_from_kaggle, task_id=check_report, execution_date=20240712T063042, start_date=20240712T063143, end_date=20240712T063147
[2024-07-12T06:31:47.658+0000] {standard_task_runner.py:107} ERROR - Failed to execute job 20 for task check_report (Process returned non-zero exit status 1.
Soda Scan failed; 941)
[2024-07-12T06:31:47.744+0000] {local_task_job_runner.py:234} INFO - Task exited with return code 1
[2024-07-12T06:31:47.878+0000] {taskinstance.py:3281} INFO - 0 downstream tasks scheduled from follow-on schedule check
