[2024-07-12T09:25:33.569+0000] {taskinstance.py:1957} INFO - Dependencies all met for dep_context=non-requeueable deps ti=<TaskInstance: store_data_from_kaggle.check_report manual__2024-07-12T09:24:42.880312+00:00 [queued]>
[2024-07-12T09:25:33.613+0000] {taskinstance.py:1957} INFO - Dependencies all met for dep_context=requeueable deps ti=<TaskInstance: store_data_from_kaggle.check_report manual__2024-07-12T09:24:42.880312+00:00 [queued]>
[2024-07-12T09:25:33.614+0000] {taskinstance.py:2171} INFO - Starting attempt 1 of 1
[2024-07-12T09:25:33.676+0000] {taskinstance.py:2192} INFO - Executing <Task(_PythonExternalDecoratedOperator): check_report> on 2024-07-12 09:24:42.880312+00:00
[2024-07-12T09:25:33.703+0000] {standard_task_runner.py:60} INFO - Started process 765 to run task
[2024-07-12T09:25:33.715+0000] {standard_task_runner.py:87} INFO - Running: ['***', 'tasks', 'run', 'store_data_from_kaggle', 'check_report', 'manual__2024-07-12T09:24:42.880312+00:00', '--job-id', '41', '--raw', '--subdir', 'DAGS_FOLDER/pipeline.py', '--cfg-path', '/tmp/tmpwcqsia4n']
[2024-07-12T09:25:33.718+0000] {standard_task_runner.py:88} INFO - Job 41: Subtask check_report
[2024-07-12T09:25:33.843+0000] {task_command.py:423} INFO - Running <TaskInstance: store_data_from_kaggle.check_report manual__2024-07-12T09:24:42.880312+00:00 [running]> on host ed07ad5522de
[2024-07-12T09:25:34.124+0000] {taskinstance.py:2481} INFO - Exporting env vars: AIRFLOW_CTX_DAG_OWNER='***' AIRFLOW_CTX_DAG_ID='store_data_from_kaggle' AIRFLOW_CTX_TASK_ID='check_report' AIRFLOW_CTX_EXECUTION_DATE='2024-07-12T09:24:42.880312+00:00' AIRFLOW_CTX_TRY_NUMBER='1' AIRFLOW_CTX_DAG_RUN_ID='manual__2024-07-12T09:24:42.880312+00:00'
[2024-07-12T09:25:34.330+0000] {python.py:903} WARNING - When checking for Airflow installed in virtual environment got Command '['/opt/airflow/soda_venv/bin/python', '-c', 'from airflow import __version__; print(__version__)']' returned non-zero exit status 1.
[2024-07-12T09:25:34.332+0000] {python.py:904} WARNING - This means that Airflow is not properly installed by  /opt/***/soda_venv/bin/python. Airflow context keys will not be available. Please Install Airflow 2.8.0 in your environment to access them.
[2024-07-12T09:25:35.547+0000] {process_utils.py:182} INFO - Executing cmd: /opt/***/soda_venv/bin/python /tmp/venv-call3dvxp9yw/script.py /tmp/venv-call3dvxp9yw/script.in /tmp/venv-call3dvxp9yw/script.out /tmp/venv-call3dvxp9yw/string_args.txt /tmp/venv-call3dvxp9yw/termination.log
[2024-07-12T09:25:35.601+0000] {process_utils.py:186} INFO - Output:
[2024-07-12T09:25:37.999+0000] {process_utils.py:190} INFO - [09:25:37] Invalid configuration header: expected "data_source {data source name}".
[2024-07-12T09:25:38.022+0000] {process_utils.py:190} INFO -   +-> line=None,col=None in /opt/***/include/soda/configuration.yml
[2024-07-12T09:25:38.726+0000] {process_utils.py:190} INFO - [09:25:38] Data source 'online_retail' not present in the configuration. Configured data sources:
[2024-07-12T09:25:38.727+0000] {process_utils.py:190} INFO - [09:25:38] No valid checks found, 0 checks evaluated.
[2024-07-12T09:25:38.728+0000] {process_utils.py:190} INFO - [09:25:38] Invalid configuration header: expected "data_source {data source name}".
[2024-07-12T09:25:38.728+0000] {process_utils.py:190} INFO -   +-> line=None,col=None in /opt/***/include/soda/configuration.yml
[2024-07-12T09:25:38.729+0000] {process_utils.py:190} INFO - [09:25:38] Data source 'online_retail' not present in the configuration. Configured data sources:
[2024-07-12T09:25:39.853+0000] {process_utils.py:190} INFO - [09:25:39] Error while executing Soda Cloud command response code: 400
[2024-07-12T09:25:39.854+0000] {process_utils.py:190} INFO - Running Soda Scan ...
[2024-07-12T09:25:39.854+0000] {process_utils.py:190} INFO - INFO   | Soda Core 3.0.45
[2024-07-12T09:25:39.854+0000] {process_utils.py:190} INFO - DEBUG  | Reading configuration file "/opt/***/include/soda/configuration.yml"
[2024-07-12T09:25:39.855+0000] {process_utils.py:190} INFO - ERROR  | Invalid configuration header: expected "data_source {data source name}". | line=None,col=None in /opt/***/include/soda/configuration.yml
[2024-07-12T09:25:39.855+0000] {process_utils.py:190} INFO - DEBUG  | Reading SodaCL file "/opt/***/include/soda/checks/report/report_customer_invoices.yml"
[2024-07-12T09:25:39.855+0000] {process_utils.py:190} INFO - DEBUG  | Reading SodaCL file "/opt/***/include/soda/checks/report/report_year_invoices.yml"
[2024-07-12T09:25:39.856+0000] {process_utils.py:190} INFO - DEBUG  | Reading SodaCL file "/opt/***/include/soda/checks/report/report_product_invoices.yml"
[2024-07-12T09:25:39.856+0000] {process_utils.py:190} INFO - DEBUG  | Scan execution starts
[2024-07-12T09:25:39.856+0000] {process_utils.py:190} INFO - ERROR  | Data source 'online_retail' not present in the configuration. Configured data sources:
[2024-07-12T09:25:39.857+0000] {process_utils.py:190} INFO - INFO   | Scan summary:
[2024-07-12T09:25:39.857+0000] {process_utils.py:190} INFO - WARNING| No valid checks found, 0 checks evaluated.
[2024-07-12T09:25:39.857+0000] {process_utils.py:190} INFO - INFO   | 2 errors.
[2024-07-12T09:25:39.857+0000] {process_utils.py:190} INFO - INFO   | Oops! 2 errors. 0 failures. 0 warnings. 0 pass.
[2024-07-12T09:25:39.866+0000] {process_utils.py:190} INFO - INFO   | Sending results to Soda Cloud
[2024-07-12T09:25:39.866+0000] {process_utils.py:190} INFO - ERROR  | Error while executing Soda Cloud command response code: 400
[2024-07-12T09:25:39.866+0000] {process_utils.py:190} INFO - DEBUG  | {
[2024-07-12T09:25:39.867+0000] {process_utils.py:190} INFO -   "type": "_ROOT",
[2024-07-12T09:25:39.867+0000] {process_utils.py:190} INFO -   "code": "invalid_request",
[2024-07-12T09:25:39.867+0000] {process_utils.py:190} INFO -   "message": "Failed validation of SodaCoreInsertScanResultsCommand on the following properties: \n logs[2].errorLocation.line: must not be empty\nlogs[2].errorLocation.col: must not be empty"
[2024-07-12T09:25:39.867+0000] {process_utils.py:190} INFO - }
[2024-07-12T09:25:39.868+0000] {process_utils.py:190} INFO - INFO   | Soda Cloud Trace: 2438435577163673049
[2024-07-12T09:25:39.868+0000] {process_utils.py:190} INFO - Traceback (most recent call last):
[2024-07-12T09:25:39.868+0000] {process_utils.py:190} INFO -   File "/tmp/venv-call3dvxp9yw/script.py", line 36, in <module>
[2024-07-12T09:25:39.868+0000] {process_utils.py:190} INFO -     res = check_report(*arg_dict["args"], **arg_dict["kwargs"])
[2024-07-12T09:25:39.869+0000] {process_utils.py:190} INFO -   File "/tmp/venv-call3dvxp9yw/script.py", line 33, in check_report
[2024-07-12T09:25:39.869+0000] {process_utils.py:190} INFO -     a = run_soda_scan(project_root = PROJECT_ROOT, scan_name ="checks_report", checks_subpath = "report")
[2024-07-12T09:25:39.869+0000] {process_utils.py:190} INFO -   File "/opt/***/include/soda/check_function.py", line 46, in run_soda_scan
[2024-07-12T09:25:39.869+0000] {process_utils.py:190} INFO -     raise ValueError('Soda Scan failed')
[2024-07-12T09:25:39.876+0000] {process_utils.py:190} INFO - ValueError: Soda Scan failed
[2024-07-12T09:25:40.013+0000] {taskinstance.py:2699} ERROR - Task failed with exception
Traceback (most recent call last):
  File "/home/airflow/.local/lib/python3.8/site-packages/airflow/models/taskinstance.py", line 433, in _execute_task
    result = execute_callable(context=context, **execute_callable_kwargs)
  File "/home/airflow/.local/lib/python3.8/site-packages/airflow/decorators/base.py", line 242, in execute
    return_value = super().execute(context)
  File "/home/airflow/.local/lib/python3.8/site-packages/airflow/operators/python.py", line 400, in execute
    return super().execute(context=serializable_context)
  File "/home/airflow/.local/lib/python3.8/site-packages/airflow/operators/python.py", line 199, in execute
    return_value = self.execute_callable()
  File "/home/airflow/.local/lib/python3.8/site-packages/airflow/operators/python.py", line 851, in execute_callable
    return self._execute_python_callable_in_subprocess(python_path)
  File "/home/airflow/.local/lib/python3.8/site-packages/airflow/operators/python.py", line 471, in _execute_python_callable_in_subprocess
    raise AirflowException(error_msg) from None
airflow.exceptions.AirflowException: Process returned non-zero exit status 1.
Soda Scan failed
[2024-07-12T09:25:40.026+0000] {taskinstance.py:1138} INFO - Marking task as FAILED. dag_id=store_data_from_kaggle, task_id=check_report, execution_date=20240712T092442, start_date=20240712T092533, end_date=20240712T092540
[2024-07-12T09:25:40.046+0000] {standard_task_runner.py:107} ERROR - Failed to execute job 41 for task check_report (Process returned non-zero exit status 1.
Soda Scan failed; 765)
[2024-07-12T09:25:40.101+0000] {local_task_job_runner.py:234} INFO - Task exited with return code 1
[2024-07-12T09:25:40.134+0000] {taskinstance.py:3281} INFO - 0 downstream tasks scheduled from follow-on schedule check
