[2024-07-12T09:13:38.054+0000] {taskinstance.py:1957} INFO - Dependencies all met for dep_context=non-requeueable deps ti=<TaskInstance: store_data_from_kaggle.check_load manual__2024-07-12T09:12:42.894898+00:00 [queued]>
[2024-07-12T09:13:38.063+0000] {taskinstance.py:1957} INFO - Dependencies all met for dep_context=requeueable deps ti=<TaskInstance: store_data_from_kaggle.check_load manual__2024-07-12T09:12:42.894898+00:00 [queued]>
[2024-07-12T09:13:38.064+0000] {taskinstance.py:2171} INFO - Starting attempt 1 of 1
[2024-07-12T09:13:38.081+0000] {taskinstance.py:2192} INFO - Executing <Task(_PythonExternalDecoratedOperator): check_load> on 2024-07-12 09:12:42.894898+00:00
[2024-07-12T09:13:38.093+0000] {standard_task_runner.py:60} INFO - Started process 225 to run task
[2024-07-12T09:13:38.099+0000] {standard_task_runner.py:87} INFO - Running: ['***', 'tasks', 'run', 'store_data_from_kaggle', 'check_load', 'manual__2024-07-12T09:12:42.894898+00:00', '--job-id', '28', '--raw', '--subdir', 'DAGS_FOLDER/pipeline.py', '--cfg-path', '/tmp/tmpuf7x33h3']
[2024-07-12T09:13:38.103+0000] {standard_task_runner.py:88} INFO - Job 28: Subtask check_load
[2024-07-12T09:13:38.165+0000] {task_command.py:423} INFO - Running <TaskInstance: store_data_from_kaggle.check_load manual__2024-07-12T09:12:42.894898+00:00 [running]> on host ed07ad5522de
[2024-07-12T09:13:38.350+0000] {taskinstance.py:2481} INFO - Exporting env vars: AIRFLOW_CTX_DAG_OWNER='***' AIRFLOW_CTX_DAG_ID='store_data_from_kaggle' AIRFLOW_CTX_TASK_ID='check_load' AIRFLOW_CTX_EXECUTION_DATE='2024-07-12T09:12:42.894898+00:00' AIRFLOW_CTX_TRY_NUMBER='1' AIRFLOW_CTX_DAG_RUN_ID='manual__2024-07-12T09:12:42.894898+00:00'
[2024-07-12T09:13:38.475+0000] {python.py:903} WARNING - When checking for Airflow installed in virtual environment got Command '['/opt/airflow/soda_venv/bin/python', '-c', 'from airflow import __version__; print(__version__)']' returned non-zero exit status 1.
[2024-07-12T09:13:38.486+0000] {python.py:904} WARNING - This means that Airflow is not properly installed by  /opt/***/soda_venv/bin/python. Airflow context keys will not be available. Please Install Airflow 2.8.0 in your environment to access them.
[2024-07-12T09:13:38.927+0000] {process_utils.py:182} INFO - Executing cmd: /opt/***/soda_venv/bin/python /tmp/venv-call1kemnt2a/script.py /tmp/venv-call1kemnt2a/script.in /tmp/venv-call1kemnt2a/script.out /tmp/venv-call1kemnt2a/string_args.txt /tmp/venv-call1kemnt2a/termination.log
[2024-07-12T09:13:38.960+0000] {process_utils.py:186} INFO - Output:
[2024-07-12T09:13:39.435+0000] {process_utils.py:190} INFO - [09:13:39] Invalid configuration header: expected "data_source {data source name}".
[2024-07-12T09:13:39.436+0000] {process_utils.py:190} INFO -   +-> line=None,col=None in /opt/***/include/soda/configuration.yml
[2024-07-12T09:13:39.471+0000] {process_utils.py:190} INFO - [09:13:39] Invalid section header "tables"
[2024-07-12T09:13:39.471+0000] {process_utils.py:190} INFO -   +-> line=1,col=1 in /opt/***/include/soda/checks/sources/checks.yml
[2024-07-12T09:13:39.775+0000] {process_utils.py:190} INFO - [09:13:39] No valid checks found, 0 checks evaluated.
[2024-07-12T09:13:39.776+0000] {process_utils.py:190} INFO - [09:13:39] Invalid configuration header: expected "data_source {data source name}".
[2024-07-12T09:13:39.776+0000] {process_utils.py:190} INFO -   +-> line=None,col=None in /opt/***/include/soda/configuration.yml
[2024-07-12T09:13:39.777+0000] {process_utils.py:190} INFO - [09:13:39] Invalid section header "tables"
[2024-07-12T09:13:39.778+0000] {process_utils.py:190} INFO -   +-> line=1,col=1 in /opt/***/include/soda/checks/sources/checks.yml
[2024-07-12T09:13:39.903+0000] {process_utils.py:190} INFO - [09:13:39] Error while executing Soda Cloud command response code: 400
[2024-07-12T09:13:39.905+0000] {process_utils.py:190} INFO - Running Soda Scan ...
[2024-07-12T09:13:39.905+0000] {process_utils.py:190} INFO - INFO   | Soda Core 3.0.45
[2024-07-12T09:13:39.906+0000] {process_utils.py:190} INFO - DEBUG  | Reading configuration file "/opt/***/include/soda/configuration.yml"
[2024-07-12T09:13:39.907+0000] {process_utils.py:190} INFO - ERROR  | Invalid configuration header: expected "data_source {data source name}". | line=None,col=None in /opt/***/include/soda/configuration.yml
[2024-07-12T09:13:39.907+0000] {process_utils.py:190} INFO - DEBUG  | Reading SodaCL file "/opt/***/include/soda/checks/sources/checks.yml"
[2024-07-12T09:13:39.908+0000] {process_utils.py:190} INFO - ERROR  | Invalid section header "tables" | line=1,col=1 in /opt/***/include/soda/checks/sources/checks.yml
[2024-07-12T09:13:39.908+0000] {process_utils.py:190} INFO - DEBUG  | Scan execution starts
[2024-07-12T09:13:39.908+0000] {process_utils.py:190} INFO - INFO   | Scan summary:
[2024-07-12T09:13:39.909+0000] {process_utils.py:190} INFO - WARNING| No valid checks found, 0 checks evaluated.
[2024-07-12T09:13:39.909+0000] {process_utils.py:190} INFO - INFO   | 2 errors.
[2024-07-12T09:13:39.910+0000] {process_utils.py:190} INFO - INFO   | Oops! 2 errors. 0 failures. 0 warnings. 0 pass.
[2024-07-12T09:13:39.910+0000] {process_utils.py:190} INFO - INFO   | Sending results to Soda Cloud
[2024-07-12T09:13:39.911+0000] {process_utils.py:190} INFO - ERROR  | Error while executing Soda Cloud command response code: 400
[2024-07-12T09:13:39.911+0000] {process_utils.py:190} INFO - DEBUG  | {
[2024-07-12T09:13:39.911+0000] {process_utils.py:190} INFO -   "type": "_ROOT",
[2024-07-12T09:13:39.912+0000] {process_utils.py:190} INFO -   "code": "invalid_request",
[2024-07-12T09:13:39.912+0000] {process_utils.py:190} INFO -   "message": "Failed validation of SodaCoreInsertScanResultsCommand on the following properties: \n logs[2].errorLocation.col: must not be empty\nlogs[2].errorLocation.line: must not be empty"
[2024-07-12T09:13:39.913+0000] {process_utils.py:190} INFO - }
[2024-07-12T09:13:39.913+0000] {process_utils.py:190} INFO - INFO   | Soda Cloud Trace: 6874712273731102946
[2024-07-12T09:13:39.913+0000] {process_utils.py:190} INFO - Traceback (most recent call last):
[2024-07-12T09:13:39.914+0000] {process_utils.py:190} INFO -   File "/tmp/venv-call1kemnt2a/script.py", line 39, in <module>
[2024-07-12T09:13:39.914+0000] {process_utils.py:190} INFO -     res = check_load(*arg_dict["args"], **arg_dict["kwargs"])
[2024-07-12T09:13:39.915+0000] {process_utils.py:190} INFO -   File "/tmp/venv-call1kemnt2a/script.py", line 36, in check_load
[2024-07-12T09:13:39.915+0000] {process_utils.py:190} INFO -     a = run_soda_scan(project_root = PROJECT_ROOT, scan_name ="checks_ingest", checks_subpath = "sources/checks.yml")
[2024-07-12T09:13:39.916+0000] {process_utils.py:190} INFO -   File "/opt/***/include/soda/check_function.py", line 46, in run_soda_scan
[2024-07-12T09:13:39.916+0000] {process_utils.py:190} INFO -     raise ValueError('Soda Scan failed')
[2024-07-12T09:13:39.917+0000] {process_utils.py:190} INFO - ValueError: Soda Scan failed
[2024-07-12T09:13:39.947+0000] {taskinstance.py:2699} ERROR - Task failed with exception
Traceback (most recent call last):
  File "/home/airflow/.local/lib/python3.8/site-packages/airflow/models/taskinstance.py", line 433, in _execute_task
    result = execute_callable(context=context, **execute_callable_kwargs)
  File "/home/airflow/.local/lib/python3.8/site-packages/airflow/decorators/base.py", line 242, in execute
    return_value = super().execute(context)
  File "/home/airflow/.local/lib/python3.8/site-packages/airflow/operators/python.py", line 400, in execute
    return super().execute(context=serializable_context)
  File "/home/airflow/.local/lib/python3.8/site-packages/airflow/operators/python.py", line 199, in execute
    return_value = self.execute_callable()
  File "/home/airflow/.local/lib/python3.8/site-packages/airflow/operators/python.py", line 851, in execute_callable
    return self._execute_python_callable_in_subprocess(python_path)
  File "/home/airflow/.local/lib/python3.8/site-packages/airflow/operators/python.py", line 471, in _execute_python_callable_in_subprocess
    raise AirflowException(error_msg) from None
airflow.exceptions.AirflowException: Process returned non-zero exit status 1.
Soda Scan failed
[2024-07-12T09:13:39.951+0000] {taskinstance.py:1138} INFO - Marking task as FAILED. dag_id=store_data_from_kaggle, task_id=check_load, execution_date=20240712T091242, start_date=20240712T091338, end_date=20240712T091339
[2024-07-12T09:13:39.967+0000] {standard_task_runner.py:107} ERROR - Failed to execute job 28 for task check_load (Process returned non-zero exit status 1.
Soda Scan failed; 225)
[2024-07-12T09:13:40.000+0000] {local_task_job_runner.py:234} INFO - Task exited with return code 1
[2024-07-12T09:13:40.022+0000] {taskinstance.py:3281} INFO - 0 downstream tasks scheduled from follow-on schedule check
