[2024-07-12T09:18:48.125+0000] {taskinstance.py:1957} INFO - Dependencies all met for dep_context=non-requeueable deps ti=<TaskInstance: store_data_from_kaggle.check_report manual__2024-07-12T09:18:40.219118+00:00 [queued]>
[2024-07-12T09:18:48.176+0000] {taskinstance.py:1957} INFO - Dependencies all met for dep_context=requeueable deps ti=<TaskInstance: store_data_from_kaggle.check_report manual__2024-07-12T09:18:40.219118+00:00 [queued]>
[2024-07-12T09:18:48.180+0000] {taskinstance.py:2171} INFO - Starting attempt 1 of 1
[2024-07-12T09:18:48.239+0000] {taskinstance.py:2192} INFO - Executing <Task(_PythonExternalDecoratedOperator): check_report> on 2024-07-12 09:18:40.219118+00:00
[2024-07-12T09:18:48.293+0000] {standard_task_runner.py:60} INFO - Started process 435 to run task
[2024-07-12T09:18:48.319+0000] {standard_task_runner.py:87} INFO - Running: ['***', 'tasks', 'run', 'store_data_from_kaggle', 'check_report', 'manual__2024-07-12T09:18:40.219118+00:00', '--job-id', '33', '--raw', '--subdir', 'DAGS_FOLDER/pipeline.py', '--cfg-path', '/tmp/tmpxd5gv971']
[2024-07-12T09:18:48.342+0000] {standard_task_runner.py:88} INFO - Job 33: Subtask check_report
[2024-07-12T09:18:48.651+0000] {task_command.py:423} INFO - Running <TaskInstance: store_data_from_kaggle.check_report manual__2024-07-12T09:18:40.219118+00:00 [running]> on host ed07ad5522de
[2024-07-12T09:18:49.185+0000] {taskinstance.py:2481} INFO - Exporting env vars: AIRFLOW_CTX_DAG_OWNER='***' AIRFLOW_CTX_DAG_ID='store_data_from_kaggle' AIRFLOW_CTX_TASK_ID='check_report' AIRFLOW_CTX_EXECUTION_DATE='2024-07-12T09:18:40.219118+00:00' AIRFLOW_CTX_TRY_NUMBER='1' AIRFLOW_CTX_DAG_RUN_ID='manual__2024-07-12T09:18:40.219118+00:00'
[2024-07-12T09:18:49.722+0000] {python.py:903} WARNING - When checking for Airflow installed in virtual environment got Command '['/opt/airflow/soda_venv/bin/python', '-c', 'from airflow import __version__; print(__version__)']' returned non-zero exit status 1.
[2024-07-12T09:18:49.731+0000] {python.py:904} WARNING - This means that Airflow is not properly installed by  /opt/***/soda_venv/bin/python. Airflow context keys will not be available. Please Install Airflow 2.8.0 in your environment to access them.
[2024-07-12T09:18:51.290+0000] {process_utils.py:182} INFO - Executing cmd: /opt/***/soda_venv/bin/python /tmp/venv-call0qw8tzhs/script.py /tmp/venv-call0qw8tzhs/script.in /tmp/venv-call0qw8tzhs/script.out /tmp/venv-call0qw8tzhs/string_args.txt /tmp/venv-call0qw8tzhs/termination.log
[2024-07-12T09:18:51.317+0000] {process_utils.py:186} INFO - Output:
[2024-07-12T09:18:53.335+0000] {process_utils.py:190} INFO - [09:18:53] Invalid configuration header: expected "data_source {data source name}".
[2024-07-12T09:18:53.336+0000] {process_utils.py:190} INFO -   +-> line=None,col=None in /opt/***/include/soda/configuration.yml
[2024-07-12T09:18:54.221+0000] {process_utils.py:190} INFO - [09:18:54] Data source 'online_retail' not present in the configuration. Configured data sources:
[2024-07-12T09:18:54.222+0000] {process_utils.py:190} INFO - [09:18:54] No valid checks found, 0 checks evaluated.
[2024-07-12T09:18:54.223+0000] {process_utils.py:190} INFO - [09:18:54] Invalid configuration header: expected "data_source {data source name}".
[2024-07-12T09:18:54.223+0000] {process_utils.py:190} INFO -   +-> line=None,col=None in /opt/***/include/soda/configuration.yml
[2024-07-12T09:18:54.224+0000] {process_utils.py:190} INFO - [09:18:54] Data source 'online_retail' not present in the configuration. Configured data sources:
[2024-07-12T09:18:54.410+0000] {process_utils.py:190} INFO - [09:18:54] Error while executing Soda Cloud command response code: 400
[2024-07-12T09:18:54.413+0000] {process_utils.py:190} INFO - Running Soda Scan ...
[2024-07-12T09:18:54.413+0000] {process_utils.py:190} INFO - INFO   | Soda Core 3.0.45
[2024-07-12T09:18:54.414+0000] {process_utils.py:190} INFO - DEBUG  | Reading configuration file "/opt/***/include/soda/configuration.yml"
[2024-07-12T09:18:54.414+0000] {process_utils.py:190} INFO - ERROR  | Invalid configuration header: expected "data_source {data source name}". | line=None,col=None in /opt/***/include/soda/configuration.yml
[2024-07-12T09:18:54.415+0000] {process_utils.py:190} INFO - DEBUG  | Reading SodaCL file "/opt/***/include/soda/checks/report/report_customer_invoices.yml"
[2024-07-12T09:18:54.415+0000] {process_utils.py:190} INFO - DEBUG  | Reading SodaCL file "/opt/***/include/soda/checks/report/report_year_invoices.yml"
[2024-07-12T09:18:54.418+0000] {process_utils.py:190} INFO - DEBUG  | Reading SodaCL file "/opt/***/include/soda/checks/report/report_product_invoices.yml"
[2024-07-12T09:18:54.418+0000] {process_utils.py:190} INFO - DEBUG  | Scan execution starts
[2024-07-12T09:18:54.421+0000] {process_utils.py:190} INFO - ERROR  | Data source 'online_retail' not present in the configuration. Configured data sources:
[2024-07-12T09:18:54.422+0000] {process_utils.py:190} INFO - INFO   | Scan summary:
[2024-07-12T09:18:54.426+0000] {process_utils.py:190} INFO - WARNING| No valid checks found, 0 checks evaluated.
[2024-07-12T09:18:54.426+0000] {process_utils.py:190} INFO - INFO   | 2 errors.
[2024-07-12T09:18:54.427+0000] {process_utils.py:190} INFO - INFO   | Oops! 2 errors. 0 failures. 0 warnings. 0 pass.
[2024-07-12T09:18:54.429+0000] {process_utils.py:190} INFO - INFO   | Sending results to Soda Cloud
[2024-07-12T09:18:54.429+0000] {process_utils.py:190} INFO - ERROR  | Error while executing Soda Cloud command response code: 400
[2024-07-12T09:18:54.430+0000] {process_utils.py:190} INFO - DEBUG  | {
[2024-07-12T09:18:54.430+0000] {process_utils.py:190} INFO -   "type": "_ROOT",
[2024-07-12T09:18:54.431+0000] {process_utils.py:190} INFO -   "code": "invalid_request",
[2024-07-12T09:18:54.432+0000] {process_utils.py:190} INFO -   "message": "Failed validation of SodaCoreInsertScanResultsCommand on the following properties: \n logs[2].errorLocation.line: must not be empty\nlogs[2].errorLocation.col: must not be empty"
[2024-07-12T09:18:54.438+0000] {process_utils.py:190} INFO - }
[2024-07-12T09:18:54.438+0000] {process_utils.py:190} INFO - INFO   | Soda Cloud Trace: 8857799254396043296
[2024-07-12T09:18:54.439+0000] {process_utils.py:190} INFO - Traceback (most recent call last):
[2024-07-12T09:18:54.439+0000] {process_utils.py:190} INFO -   File "/tmp/venv-call0qw8tzhs/script.py", line 36, in <module>
[2024-07-12T09:18:54.450+0000] {process_utils.py:190} INFO -     res = check_report(*arg_dict["args"], **arg_dict["kwargs"])
[2024-07-12T09:18:54.453+0000] {process_utils.py:190} INFO -   File "/tmp/venv-call0qw8tzhs/script.py", line 33, in check_report
[2024-07-12T09:18:54.453+0000] {process_utils.py:190} INFO -     a = run_soda_scan(project_root = PROJECT_ROOT, scan_name ="checks_report", checks_subpath = "report")
[2024-07-12T09:18:54.454+0000] {process_utils.py:190} INFO -   File "/opt/***/include/soda/check_function.py", line 46, in run_soda_scan
[2024-07-12T09:18:54.454+0000] {process_utils.py:190} INFO -     raise ValueError('Soda Scan failed')
[2024-07-12T09:18:54.455+0000] {process_utils.py:190} INFO - ValueError: Soda Scan failed
[2024-07-12T09:18:54.657+0000] {taskinstance.py:2699} ERROR - Task failed with exception
Traceback (most recent call last):
  File "/home/airflow/.local/lib/python3.8/site-packages/airflow/models/taskinstance.py", line 433, in _execute_task
    result = execute_callable(context=context, **execute_callable_kwargs)
  File "/home/airflow/.local/lib/python3.8/site-packages/airflow/decorators/base.py", line 242, in execute
    return_value = super().execute(context)
  File "/home/airflow/.local/lib/python3.8/site-packages/airflow/operators/python.py", line 400, in execute
    return super().execute(context=serializable_context)
  File "/home/airflow/.local/lib/python3.8/site-packages/airflow/operators/python.py", line 199, in execute
    return_value = self.execute_callable()
  File "/home/airflow/.local/lib/python3.8/site-packages/airflow/operators/python.py", line 851, in execute_callable
    return self._execute_python_callable_in_subprocess(python_path)
  File "/home/airflow/.local/lib/python3.8/site-packages/airflow/operators/python.py", line 471, in _execute_python_callable_in_subprocess
    raise AirflowException(error_msg) from None
airflow.exceptions.AirflowException: Process returned non-zero exit status 1.
Soda Scan failed
[2024-07-12T09:18:54.671+0000] {taskinstance.py:1138} INFO - Marking task as FAILED. dag_id=store_data_from_kaggle, task_id=check_report, execution_date=20240712T091840, start_date=20240712T091848, end_date=20240712T091854
[2024-07-12T09:18:54.712+0000] {standard_task_runner.py:107} ERROR - Failed to execute job 33 for task check_report (Process returned non-zero exit status 1.
Soda Scan failed; 435)
[2024-07-12T09:18:54.812+0000] {local_task_job_runner.py:234} INFO - Task exited with return code 1
[2024-07-12T09:18:54.881+0000] {taskinstance.py:3281} INFO - 0 downstream tasks scheduled from follow-on schedule check
